Workbook

Sheet Summary
A1: Oregon LIHTC off-market sourcing: lead tracker
A2: ="As of "&TEXT(Scoring!B3,"mmmm d, yyyy")&". Universe: HUD LIHTC database extract for Oregon (uploaded LIHTC.xlsx). Scores are provisional until the yellow columns on the Leads tab are filled in." -> As of October 2, 2026. Universe: HUD LIHTC database extract for Oregon (uploaded LIHTC.xlsx). Scores are provisional until the yellow columns on the Leads tab are filled in.
A4: Search summary
A5: Metric | B5: Count | C5: Units
A6: Records scanned | B6: =COUNTA(Leads!$E$2:$E$755) -> 754 | C6: =SUM(Leads!$J$2:$J$755) -> 45401
A7: Superseded or duplicate records | B7: =COUNTIF(Leads!$T$2:$T$755,"Y") -> 12 | C7: =SUMIF(Leads!$T$2:$T$755,"Y",Leads!$J$2:$J$755) -> 711
A8: Unique leads scored | B8: =B6-B7 -> 742 | C8: =C6-C7 -> 44690
A9: Out of LIHTC program (HUD: no longer monitored) | B9: =COUNTIF(Leads!$D$2:$D$755,"Out of program") -> 105 | C9: =SUMIF(Leads!$D$2:$D$755,"Out of program",Leads!$J$2:$J$755) -> 2339
A10: Below the 5-unit PuSH-CP threshold | B10: =COUNTIF(Leads!$R$2:$R$755,"No (under 5 units)") -> 73 | C10: =SUMIF(Leads!$R$2:$R$755,"No (under 5 units)",Leads!$J$2:$J$755) -> 110
A11: Verified expiration dates entered | B11: =COUNT(Leads!$U$2:$U$755) -> 0
A13: Pipeline actions by tier
A14: Tier | B14: Leads | C14: Units | D14: Share of leads | E14: Action
A15: Immediate | B15: =COUNTIF(Leads!$B$2:$B$755,A15) -> 8 | C15: =SUMIF(Leads!$B$2:$B$755,A15,Leads!$J$2:$J$755) -> 706 | D15: =IF($B$19=0,0,B15/$B$19) -> 0.010781671 | E15: Verify the restriction end date and owner this week; open direct owner or GP outreach.
A16: This week | B16: =COUNTIF(Leads!$B$2:$B$755,A16) -> 361 | C16: =SUMIF(Leads!$B$2:$B$755,A16,Leads!$J$2:$J$755) -> 21917 | D16: =IF($B$19=0,0,B16/$B$19) -> 0.48652291 | E16: Pull the OHCS expiration forecast and county ownership records; fill the yellow columns; re-rank.
A17: Nurture | B17: =COUNTIF(Leads!$B$2:$B$755,A17) -> 285 | C17: =SUMIF(Leads!$B$2:$B$755,A17,Leads!$J$2:$J$755) -> 14234 | D17: =IF($B$19=0,0,B17/$B$19) -> 0.38409704 | E17: Add to a quarterly watch list; re-score when vintage ages into a window.
A18: Low | B18: =COUNTIF(Leads!$B$2:$B$755,A18) -> 88 | C18: =SUMIF(Leads!$B$2:$B$755,A18,Leads!$J$2:$J$755) -> 7833 | D18: =IF($B$19=0,0,B18/$B$19) -> 0.11859838 | E18: No action; inside the credit period or no signal.
A19: Total | B19: =SUM(B15:B18) -> 742 | C19: =SUM(C15:C18) -> 44690 | E19: =IF(B19=B8,"Ties to unique leads scored","CHECK: does not tie to unique leads") -> Ties to unique leads scored
A21: Signal distribution by play
A22: Play / lifecycle stage | B22: Leads | C22: Units | D22: Avg score | E22: What it means
A23: Expiring: notice window (verified) | B23: =COUNTIF(Leads!$D$2:$D$755,A23) -> 0 | C23: =SUMIF(Leads!$D$2:$D$755,A23,Leads!$J$2:$J$755) -> 0 | D23: =IFERROR(AVERAGEIF(Leads!$D$2:$D$755,A23,Leads!$C$2:$C$755),0) -> 0 | E23: Verified affordability end date inside the Oregon owner-notice window. Highest-priority outreach.
A24: Expired (verified) | B24: =COUNTIF(Leads!$D$2:$D$755,A24) -> 0 | C24: =SUMIF(Leads!$D$2:$D$755,A24,Leads!$J$2:$J$755) -> 0 | D24: =IFERROR(AVERAGEIF(Leads!$D$2:$D$755,A24,Leads!$C$2:$C$755),0) -> 0 | E24: Verified end date has passed; tenant safe-harbour and any recorded right of first refusal may still apply.
A25: Expiring: 10-yr horizon (verified) | B25: =COUNTIF(Leads!$D$2:$D$755,A25) -> 0 | C25: =SUMIF(Leads!$D$2:$D$755,A25,Leads!$J$2:$J$755) -> 0 | D25: =IFERROR(AVERAGEIF(Leads!$D$2:$D$755,A25,Leads!$C$2:$C$755),0) -> 0 | E25: Verified end date inside the 10-year forecast horizon.
A26: 30-yr mark: notice window (est.) | B26: =COUNTIF(Leads!$D$2:$D$755,A26) -> 83 | C26: =SUMIF(Leads!$D$2:$D$755,A26,Leads!$J$2:$J$755) -> 5724 | D26: =IFERROR(AVERAGEIF(Leads!$D$2:$D$755,A26,Leads!$C$2:$C$755),0) -> 70.674699 | E26: Federal minimum 30-year period closes within the notice window. Confirm the REUA term; many run longer.
A27: Past 30-yr mark (verify) | B27: =COUNTIF(Leads!$D$2:$D$755,A27) -> 105 | C27: =SUMIF(Leads!$D$2:$D$755,A27,Leads!$J$2:$J$755) -> 6849 | D27: =IFERROR(AVERAGEIF(Leads!$D$2:$D$755,A27,Leads!$C$2:$C$755),0) -> 64.2 | E27: Older than the federal 30-year minimum but still listed as monitored: either a longer state restriction or a recent expiry.
A28: Year-15 window | B28: =COUNTIF(Leads!$D$2:$D$755,A28) -> 110 | C28: =SUMIF(Leads!$D$2:$D$755,A28,Leads!$J$2:$J$755) -> 5917 | D28: =IFERROR(AVERAGEIF(Leads!$D$2:$D$755,A28,Leads!$C$2:$C$755),0) -> 56.4 | E28: Compliance period closing; limited partner exit, GP buyout or third-party sale in play.
A29: Recap window | B29: =COUNTIF(Leads!$D$2:$D$755,A29) -> 206 | C29: =SUMIF(Leads!$D$2:$D$755,A29,Leads!$J$2:$J$755) -> 13926 | D29: =IFERROR(AVERAGEIF(Leads!$D$2:$D$755,A29,Leads!$C$2:$C$755),0) -> 47.669903 | E29: Years 18 and later of extended use; recapitalisation or resyndication candidate.
A30: Out of program | B30: =COUNTIF(Leads!$D$2:$D$755,A30) -> 105 | C30: =SUMIF(Leads!$D$2:$D$755,A30,Leads!$J$2:$J$755) -> 2339 | D30: =IFERROR(AVERAGEIF(Leads!$D$2:$D$755,A30,Leads!$C$2:$C$755),0) -> 44.666667 | E30: HUD shows no longer monitored. Treat as a conventional asset and confirm current ownership.
A31: Pre-1990, still listed | B31: =COUNTIF(Leads!$D$2:$D$755,A31) -> 18 | C31: =SUMIF(Leads!$D$2:$D$755,A31,Leads!$J$2:$J$755) -> 259 | D31: =IFERROR(AVERAGEIF(Leads!$D$2:$D$755,A31,Leads!$C$2:$C$755),0) -> 52 | E31: Pre-1990 allocation (15-year compliance only) still shown as active; likely stale data or another subsidy layer.
A32: Late compliance | B32: =COUNTIF(Leads!$D$2:$D$755,A32) -> 27 | C32: =SUMIF(Leads!$D$2:$D$755,A32,Leads!$J$2:$J$755) -> 1750 | D32: =IFERROR(AVERAGEIF(Leads!$D$2:$D$755,A32,Leads!$C$2:$C$755),0) -> 33.740741 | E32: Years 11 to 12; too early for an exit conversation.
A33: Credit period | B33: =COUNTIF(Leads!$D$2:$D$755,A33) -> 85 | C33: =SUMIF(Leads!$D$2:$D$755,A33,Leads!$J$2:$J$755) -> 7853 | D33: =IFERROR(AVERAGEIF(Leads!$D$2:$D$755,A33,Leads!$C$2:$C$755),0) -> 24.388235 | E33: Inside the 10-year credit period; not a lead.
A34: Unknown vintage | B34: =COUNTIF(Leads!$D$2:$D$755,A34) -> 3 | C34: =SUMIF(Leads!$D$2:$D$755,A34,Leads!$J$2:$J$755) -> 73 | D34: =IFERROR(AVERAGEIF(Leads!$D$2:$D$755,A34,Leads!$C$2:$C$755),0) -> 29 | E34: HUD ID carries no year.
A35: Superseded record | B35: =COUNTIF(Leads!$D$2:$D$755,A35) -> 12 | C35: =SUMIF(Leads!$D$2:$D$755,A35,Leads!$J$2:$J$755) -> 711 | D35: =IFERROR(AVERAGEIF(Leads!$D$2:$D$755,A35,Leads!$C$2:$C$755),0) -> 0 | E35: Replaced by a later allocation at the same address, or a duplicate row.
A36: Total | B36: =SUM(B23:B35) -> 754 | C36: =SUM(C23:C35) -> 45401 | E36: =IF(B36=B6,"Ties to records scanned","CHECK: does not tie to records scanned") -> Ties to records scanned
A38: Top 40 leads (live ranking; ties broken by unit count)
A39: Rank | B39: Project name | C39: City | D39: Units | E39: Play / lifecycle stage | F39: Vintage | G39: Score | H39: Tier | I39: HUD ID
A40: 1 | B40: =INDEX(Leads!$F$2:$F$755,MATCH($A40,Leads!$A$2:$A$755,0)) -> VILLAGE AT LOVEJOY FOUNTAIN | C40: =INDEX(Leads!$H$2:$H$755,MATCH($A40,Leads!$A$2:$A$755,0)) -> PORTLAND | D40: =INDEX(Leads!$J$2:$J$755,MATCH($A40,Leads!$A$2:$A$755,0)) -> 198 | E40: =INDEX(Leads!$D$2:$D$755,MATCH($A40,Leads!$A$2:$A$755,0)) -> 30-yr mark: notice window (est.) | F40: =INDEX(Leads!$N$2:$N$755,MATCH($A40,Leads!$A$2:$A$755,0)) -> 1999 | G40: =INDEX(Leads!$C$2:$C$755,MATCH($A40,Leads!$A$2:$A$755,0)) -> 77 | H40: =INDEX(Leads!$B$2:$B$755,MATCH($A40,Leads!$A$2:$A$755,0)) -> Immediate | I40: =INDEX(Leads!$E$2:$E$755,MATCH($A40,Leads!$A$2:$A$755,0)) -> ORA19990155
A41: 2 | B41: =INDEX(Leads!$F$2:$F$755,MATCH($A41,Leads!$A$2:$A$755,0)) -> ST ANTHONY VILLAGE | C41: =INDEX(Leads!$H$2:$H$755,MATCH($A41,Leads!$A$2:$A$755,0)) -> PORTLAND | D41: =INDEX(Leads!$J$2:$J$755,MATCH($A41,Leads!$A$2:$A$755,0)) -> 128 | E41: =INDEX(Leads!$D$2:$D$755,MATCH($A41,Leads!$A$2:$A$755,0)) -> 30-yr mark: notice window (est.) | F41: =INDEX(Leads!$N$2:$N$755,MATCH($A41,Leads!$A$2:$A$755,0)) -> 1999 | G41: =INDEX(Leads!$C$2:$C$755,MATCH($A41,Leads!$A$2:$A$755,0)) -> 77 | H41: =INDEX(Leads!$B$2:$B$755,MATCH($A41,Leads!$A$2:$A$755,0)) -> Immediate | I41: =INDEX(Leads!$E$2:$E$755,MATCH($A41,Leads!$A$2:$A$755,0)) -> ORA19990140
A42: 3 | B42: =INDEX(Leads!$F$2:$F$755,MATCH($A42,Leads!$A$2:$A$755,0)) -> PARKWAY VILLAGE APTS - SALEM | C42: =INDEX(Leads!$H$2:$H$755,MATCH($A42,Leads!$A$2:$A$755,0)) -> SALEM | D42: =INDEX(Leads!$J$2:$J$755,MATCH($A42,Leads!$A$2:$A$755,0)) -> 124 | E42: =INDEX(Leads!$D$2:$D$755,MATCH($A42,Leads!$A$2:$A$755,0)) -> 30-yr mark: notice window (est.) | F42: =INDEX(Leads!$N$2:$N$755,MATCH($A42,Leads!$A$2:$A$755,0)) -> 1997 | G42: =INDEX(Leads!$C$2:$C$755,MATCH($A42,Leads!$A$2:$A$755,0)) -> 77 | H42: =INDEX(Leads!$B$2:$B$755,MATCH($A42,Leads!$A$2:$A$755,0)) -> Immediate | I42: =INDEX(Leads!$E$2:$E$755,MATCH($A42,Leads!$A$2:$A$755,0)) -> ORA19970141
A43: 4 | B43: =INDEX(Leads!$F$2:$F$755,MATCH($A43,Leads!$A$2:$A$755,0)) -> FIFTH AVE COURTS | C43: =INDEX(Leads!$H$2:$H$755,MATCH($A43,Leads!$A$2:$A$755,0)) -> PORTLAND | D43: =INDEX(Leads!$J$2:$J$755,MATCH($A43,Leads!$A$2:$A$755,0)) -> 96 | E43: =INDEX(Leads!$D$2:$D$755,MATCH($A43,Leads!$A$2:$A$755,0)) -> 30-yr mark: notice window (est.) | F43: =INDEX(Leads!$N$2:$N$755,MATCH($A43,Leads!$A$2:$A$755,0)) -> 1999 | G43: =INDEX(Leads!$C$2:$C$755,MATCH($A43,Leads!$A$2:$A$755,0)) -> 77 | H43: =INDEX(Leads!$B$2:$B$755,MATCH($A43,Leads!$A$2:$A$755,0)) -> Immediate | I43: =INDEX(Leads!$E$2:$E$755,MATCH($A43,Leads!$A$2:$A$755,0)) -> ORA19990055
A44: 5 | B44: =INDEX(Leads!$F$2:$F$755,MATCH($A44,Leads!$A$2:$A$755,0)) -> FLOYD LIGHT APTS | C44: =INDEX(Leads!$H$2:$H$755,MATCH($A44,Leads!$A$2:$A$755,0)) -> PORTLAND | D44: =INDEX(Leads!$J$2:$J$755,MATCH($A44,Leads!$A$2:$A$755,0)) -> 51 | E44: =INDEX(Leads!$D$2:$D$755,MATCH($A44,Leads!$A$2:$A$755,0)) -> 30-yr mark: notice window (est.) | F44: =INDEX(Leads!$N$2:$N$755,MATCH($A44,Leads!$A$2:$A$755,0)) -> 1997 | G44: =INDEX(Leads!$C$2:$C$755,MATCH($A44,Leads!$A$2:$A$755,0)) -> 77 | H44: =INDEX(Leads!$B$2:$B$755,MATCH($A44,Leads!$A$2:$A$755,0)) -> Immediate | I44: =INDEX(Leads!$E$2:$E$755,MATCH($A44,Leads!$A$2:$A$755,0)) -> ORA19970035
...

Sheet Leads
A1: Rank | B1: Tier | C1: Score | D1: Play / lifecycle stage | E1: HUD ID | F1: Project name | G1: Address | H1: City | I1: ZIP | J1: Total units | K1: Low-income units | L1: Market-rate units | M1: HUD monitoring status | N1: Vintage (HUD ID year) | O1: Age (yrs) | P1: Year-15 close (est.) | Q1: 30-yr mark, federal minimum (est.) | R1: PuSH-CP size test (5+ units) | S1: Record flag | T1: Superseded? (Y) | U1: Verified expiration date | V1: Last transfer year | W1: Owner type | X1: Est. equity % | Y1: Distress flag (Y) | Z1: Other verified signals (0-3) | AA1: Years to expiration | AB1: Signals (count) | AC1: Stacking pts | AD1: Equity pts | AE1: Time pts | AF1: Tenure pts | AG1: Condition pts | AH1: Owner pts | AI1: Sort key | AJ1: Owner / GP entity | AK1: Contact | AL1: Outreach status | AM1: Notes / next step
A2: =RANK(AI2,$AI$2:$AI$755) -> 1 | B2: =IF(T2="Y","Superseded",IF(C2>=Scoring!$B$16,"Immediate",IF(C2>=Scoring!$B$17,"This week",IF(C2>=Scoring!$B$18,"Nurture","Low")))) -> Immediate | C2: =SUM(AC2:AH2) -> 77 | D2: =IF(T2="Y","Superseded record",IF(AND(U2<>"",AA2<0),"Expired (verified)",IF(AND(U2<>"",AA2<=Scoring!$B$5),"Expiring: notice window (verified)",IF(AND(U2<>"",AA2<=Scoring!$B$6),"Expiring: 10-yr horizon (verified)",IF(M2="No Longer Monitored","Out of program",IF(N2="","Unknown vintage",IF(N2<Scoring!$B$12,"Pre-1990, still listed",IF(AND(U2="",AA2<0),"Past 30-yr mark (verify)",IF(AND(U2="",AA2<=Scoring!$B$5),"30-yr mark: notice window (est.)",IF(AND(O2>=Scoring!$B$7,O2<=Scoring!$B$8),"Year-15 window",IF(O2>=Scoring!$B$9,"Recap window",IF(O2>=11,"Late compliance","Credit period")))))))))))) -> 30-yr mark: notice window (est.) | E2: ORA19990155 | F2: VILLAGE AT LOVEJOY FOUNTAIN | G2: 245 SW LINCOLN ST | H2: PORTLAND | I2: 97201 | J2: 198 | K2: 40 | L2: =IF(OR(J2="",K2=""),"",MAX(J2-K2,0)) -> 158 | M2: Not Indicated | N2: 1999 | O2: =IF(N2="","",Scoring!$B$4-N2) -> 27 | P2: =IF(N2="","",N2+14) -> 2013 | Q2: =IF(N2="","",IF(N2<Scoring!$B$12,"n/a (pre-1990)",N2+Scoring!$B$13)) -> 2028 | R2: =IF(J2="","Unknown",IF(J2>=5,"Yes","No (under 5 units)")) -> Yes | AA2: =IF(U2<>"",(U2-Scoring!$B$3)/365.25,IF(N2="","",IF(N2<Scoring!$B$12,"",(DATE(N2+Scoring!$B$13,12,31)-Scoring!$B$3)/365.25))) -> 2.2477755 | AB2: =IF(T2="Y",0,IF(OR(D2="Expired (verified)",D2="Expiring: notice window (verified)",D2="Expiring: 10-yr horizon (verified)",D2="Past 30-yr mark (verify)",D2="30-yr mark: notice window (est.)",D2="Year-15 window"),1,0)+IF(ISNUMBER(O2),IF(O2>=Scoring!$B$10,1,0),0)+IF(AND(ISNUMBER(L2),ISNUMBER(J2)),IF(J2>0,IF(L2/J2>=Scoring!$B$11,1,0),0),0)+IF(ISNUMBER(Z2),MIN(Z2,3),0)) -> 3 | AC2: =IF(AB2>=3,Scoring!$C$24,IF(AB2=2,Scoring!$C$23,IF(AB2=1,Scoring!$C$22,0))) -> 25 | AD2: =IF(T2="Y",0,IF(ISNUMBER(X2),IF(X2>0.7,Scoring!$C$25,IF(X2>=0.5,Scoring!$C$26,IF(X2>=0.3,Scoring!$C$27,Scoring!$C$28))),Scoring!$C$29)) -> 10 | AE2: =IF(D2="Expiring: notice window (verified)",Scoring!$C$30,IF(OR(D2="Expired (verified)",D2="30-yr mark: notice window (est.)",D2="Year-15 window"),Scoring!$C$31,IF(D2="Expiring: 10-yr horizon (verified)",Scoring!$C$32,IF(D2="Past 30-yr mark (verify)",Scoring!$C$33,IF(OR(D2="Credit period",D2="Superseded record"),Scoring!$C$35,Scoring!$C$34))))) -> 14 | AF2: =IF(T2="Y",0,IF(ISNUMBER(V2),IF(Scoring!$B$4-V2>15,Scoring!$C$36,IF(Scoring!$B$4-V2>=10,Scoring!$C$37,IF(Scoring!$B$4-V2>=5,Scoring!$C$38,Scoring!$C$39))),IF(OR(N2="",D2="Out of program"),Scoring!$C$40,IF(O2>15,Scoring!$C$36,IF(O2>=10,Scoring!$C$37,IF(O2>=5,Scoring!$C$38,Scoring!$C$39)))))) -> 15 | AG2: =IF(T2="Y",0,IF(Y2="Y",Scoring!$C$41,IF(ISNUMBER(O2),IF(O2>=25,Scoring!$C$42,IF(O2>=15,Scoring!$C$43,Scoring!$C$44)),Scoring!$C$44))) -> 8 | AH2: =IF(T2="Y",0,IF(W2="",Scoring!$C$49,IFERROR(VLOOKUP(W2,Scoring!$B$45:$C$48,2,FALSE()),Scoring!$C$49))) -> 5 | AI2: =C2+IF(ISNUMBER(J2),J2,0)/100000+(10000-ROW())/1000000000 -> 77.00199
A3: =RANK(AI3,$AI$2:$AI$755) -> 2 | B3: =IF(T3="Y","Superseded",IF(C3>=Scoring!$B$16,"Immediate",IF(C3>=Scoring!$B$17,"This week",IF(C3>=Scoring!$B$18,"Nurture","Low")))) -> Immediate | C3: =SUM(AC3:AH3) -> 77 | D3: =IF(T3="Y","Superseded record",IF(AND(U3<>"",AA3<0),"Expired (verified)",IF(AND(U3<>"",AA3<=Scoring!$B$5),"Expiring: notice window (verified)",IF(AND(U3<>"",AA3<=Scoring!$B$6),"Expiring: 10-yr horizon (verified)",IF(M3="No Longer Monitored","Out of program",IF(N3="","Unknown vintage",IF(N3<Scoring!$B$12,"Pre-1990, still listed",IF(AND(U3="",AA3<0),"Past 30-yr mark (verify)",IF(AND(U3="",AA3<=Scoring!$B$5),"30-yr mark: notice window (est.)",IF(AND(O3>=Scoring!$B$7,O3<=Scoring!$B$8),"Year-15 window",IF(O3>=Scoring!$B$9,"Recap window",IF(O3>=11,"Late compliance","Credit period")))))))))))) -> 30-yr mark: notice window (est.) | E3: ORA19990140 | F3: ST ANTHONY VILLAGE | G3: 3560 SE 79TH AVE | H3: PORTLAND | I3: 97206 | J3: 128 | K3: 106 | L3: =IF(OR(J3="",K3=""),"",MAX(J3-K3,0)) -> 22 | M3: Not Indicated | N3: 1999 | O3: =IF(N3="","",Scoring!$B$4-N3) -> 27 | P3: =IF(N3="","",N3+14) -> 2013 | Q3: =IF(N3="","",IF(N3<Scoring!$B$12,"n/a (pre-1990)",N3+Scoring!$B$13)) -> 2028 | R3: =IF(J3="","Unknown",IF(J3>=5,"Yes","No (under 5 units)")) -> Yes | AA3: =IF(U3<>"",(U3-Scoring!$B$3)/365.25,IF(N3="","",IF(N3<Scoring!$B$12,"",(DATE(N3+Scoring!$B$13,12,31)-Scoring!$B$3)/365.25))) -> 2.2477755 | AB3: =IF(T3="Y",0,IF(OR(D3="Expired (verified)",D3="Expiring: notice window (verified)",D3="Expiring: 10-yr horizon (verified)",D3="Past 30-yr mark (verify)",D3="30-yr mark: notice window (est.)",D3="Year-15 window"),1,0)+IF(ISNUMBER(O3),IF(O3>=Scoring!$B$10,1,0),0)+IF(AND(ISNUMBER(L3),ISNUMBER(J3)),IF(J3>0,IF(L3/J3>=Scoring!$B$11,1,0),0),0)+IF(ISNUMBER(Z3),MIN(Z3,3),0)) -> 3 | AC3: =IF(AB3>=3,Scoring!$C$24,IF(AB3=2,Scoring!$C$23,IF(AB3=1,Scoring!$C$22,0))) -> 25 | AD3: =IF(T3="Y",0,IF(ISNUMBER(X3),IF(X3>0.7,Scoring!$C$25,IF(X3>=0.5,Scoring!$C$26,IF(X3>=0.3,Scoring!$C$27,Scoring!$C$28))),Scoring!$C$29)) -> 10 | AE3: =IF(D3="Expiring: notice window (verified)",Scoring!$C$30,IF(OR(D3="Expired (verified)",D3="30-yr mark: notice window (est.)",D3="Year-15 window"),Scoring!$C$31,IF(D3="Expiring: 10-yr horizon (verified)",Scoring!$C$32,IF(D3="Past 30-yr mark (verify)",Scoring!$C$33,IF(OR(D3="Credit period",D3="Superseded record"),Scoring!$C$35,Scoring!$C$34))))) -> 14 | AF3: =IF(T3="Y",0,IF(ISNUMBER(V3),IF(Scoring!$B$4-V3>15,Scoring!$C$36,IF(Scoring!$B$4-V3>=10,Scoring!$C$37,IF(Scoring!$B$4-V3>=5,Scoring!$C$38,Scoring!$C$39))),IF(OR(N3="",D3="Out of program"),Scoring!$C$40,IF(O3>15,Scoring!$C$36,IF(O3>=10,Scoring!$C$37,IF(O3>=5,Scoring!$C$38,Scoring!$C$39)))))) -> 15 | AG3: =IF(T3="Y",0,IF(Y3="Y",Scoring!$C$41,IF(ISNUMBER(O3),IF(O3>=25,Scoring!$C$42,IF(O3>=15,Scoring!$C$43,Scoring!$C$44)),Scoring!$C$44))) -> 8 | AH3: =IF(T3="Y",0,IF(W3="",Scoring!$C$49,IFERROR(VLOOKUP(W3,Scoring!$B$45:$C$48,2,FALSE()),Scoring!$C$49))) -> 5 | AI3: =C3+IF(ISNUMBER(J3),J3,0)/100000+(10000-ROW())/1000000000 -> 77.00129
A4: =RANK(AI4,$AI$2:$AI$755) -> 3 | B4: =IF(T4="Y","Superseded",IF(C4>=Scoring!$B$16,"Immediate",IF(C4>=Scoring!$B$17,"This week",IF(C4>=Scoring!$B$18,"Nurture","Low")))) -> Immediate | C4: =SUM(AC4:AH4) -> 77 | D4: =IF(T4="Y","Superseded record",IF(AND(U4<>"",AA4<0),"Expired (verified)",IF(AND(U4<>"",AA4<=Scoring!$B$5),"Expiring: notice window (verified)",IF(AND(U4<>"",AA4<=Scoring!$B$6),"Expiring: 10-yr horizon (verified)",IF(M4="No Longer Monitored","Out of program",IF(N4="","Unknown vintage",IF(N4<Scoring!$B$12,"Pre-1990, still listed",IF(AND(U4="",AA4<0),"Past 30-yr mark (verify)",IF(AND(U4="",AA4<=Scoring!$B$5),"30-yr mark: notice window (est.)",IF(AND(O4>=Scoring!$B$7,O4<=Scoring!$B$8),"Year-15 window",IF(O4>=Scoring!$B$9,"Recap window",IF(O4>=11,"Late compliance","Credit period")))))))))))) -> 30-yr mark: notice window (est.) | E4: ORA19970141 | F4: PARKWAY VILLAGE APTS - SALEM | G4: 3143 SEVENTH PL NE | H4: SALEM | I4: 97303 | J4: 124 | K4: 100 | L4: =IF(OR(J4="",K4=""),"",MAX(J4-K4,0)) -> 24 | M4: Not Indicated | N4: 1997 | O4: =IF(N4="","",Scoring!$B$4-N4) -> 29 | P4: =IF(N4="","",N4+14) -> 2011 | Q4: =IF(N4="","",IF(N4<Scoring!$B$12,"n/a (pre-1990)",N4+Scoring!$B$13)) -> 2026 | R4: =IF(J4="","Unknown",IF(J4>=5,"Yes","No (under 5 units)")) -> Yes | AA4: =IF(U4<>"",(U4-Scoring!$B$3)/365.25,IF(N4="","",IF(N4<Scoring!$B$12,"",(DATE(N4+Scoring!$B$13,12,31)-Scoring!$B$3)/365.25))) -> 0.24640657 | AB4: =IF(T4="Y",0,IF(OR(D4="Expired (verified)",D4="Expiring: notice window (verified)",D4="Expiring: 10-yr horizon (verified)",D4="Past 30-yr mark (verify)",D4="30-yr mark: notice window (est.)",D4="Year-15 window"),1,0)+IF(ISNUMBER(O4),IF(O4>=Scoring!$B$10,1,0),0)+IF(AND(ISNUMBER(L4),ISNUMBER(J4)),IF(J4>0,IF(L4/J4>=Scoring!$B$11,1,0),0),0)+IF(ISNUMBER(Z4),MIN(Z4,3),0)) -> 3 | AC4: =IF(AB4>=3,Scoring!$C$24,IF(AB4=2,Scoring!$C$23,IF(AB4=1,Scoring!$C$22,0))) -> 25 | AD4: =IF(T4="Y",0,IF(ISNUMBER(X4),IF(X4>0.7,Scoring!$C$25,IF(X4>=0.5,Scoring!$C$26,IF(X4>=0.3,Scoring!$C$27,Scoring!$C$28))),Scoring!$C$29)) -> 10 | AE4: =IF(D4="Expiring: notice window (verified)",Scoring!$C$30,IF(OR(D4="Expired (verified)",D4="30-yr mark: notice window (est.)",D4="Year-15 window"),Scoring!$C$31,IF(D4="Expiring: 10-yr horizon (verified)",Scoring!$C$32,IF(D4="Past 30-yr mark (verify)",Scoring!$C$33,IF(OR(D4="Credit period",D4="Superseded record"),Scoring!$C$35,Scoring!$C$34))))) -> 14 | AF4: =IF(T4="Y",0,IF(ISNUMBER(V4),IF(Scoring!$B$4-V4>15,Scoring!$C$36,IF(Scoring!$B$4-V4>=10,Scoring!$C$37,IF(Scoring!$B$4-V4>=5,Scoring!$C$38,Scoring!$C$39))),IF(OR(N4="",D4="Out of program"),Scoring!$C$40,IF(O4>15,Scoring!$C$36,IF(O4>=10,Scoring!$C$37,IF(O4>=5,Scoring!$C$38,Scoring!$C$39)))))) -> 15 | AG4: =IF(T4="Y",0,IF(Y4="Y",Scoring!$C$41,IF(ISNUMBER(O4),IF(O4>=25,Scoring!$C$42,IF(O4>=15,Scoring!$C$43,Scoring!$C$44)),Scoring!$C$44))) -> 8 | AH4: =IF(T4="Y",0,IF(W4="",Scoring!$C$49,IFERROR(VLOOKUP(W4,Scoring!$B$45:$C$48,2,FALSE()),Scoring!$C$49))) -> 5 | AI4: =C4+IF(ISNUMBER(J4),J4,0)/100000+(10000-ROW())/1000000000 -> 77.00125
A5: =RANK(AI5,$AI$2:$AI$755) -> 4 | B5: =IF(T5="Y","Superseded",IF(C5>=Scoring!$B$16,"Immediate",IF(C5>=Scoring!$B$17,"This week",IF(C5>=Scoring!$B$18,"Nurture","Low")))) -> Immediate | C5: =SUM(AC5:AH5) -> 77 | D5: =IF(T5="Y","Superseded record",IF(AND(U5<>"",AA5<0),"Expired (verified)",IF(AND(U5<>"",AA5<=Scoring!$B$5),"Expiring: notice window (verified)",IF(AND(U5<>"",AA5<=Scoring!$B$6),"Expiring: 10-yr horizon (verified)",IF(M5="No Longer Monitored","Out of program",IF(N5="","Unknown vintage",IF(N5<Scoring!$B$12,"Pre-1990, still listed",IF(AND(U5="",AA5<0),"Past 30-yr mark (verify)",IF(AND(U5="",AA5<=Scoring!$B$5),"30-yr mark: notice window (est.)",IF(AND(O5>=Scoring!$B$7,O5<=Scoring!$B$8),"Year-15 window",IF(O5>=Scoring!$B$9,"Recap window",IF(O5>=11,"Late compliance","Credit period")))))))))))) -> 30-yr mark: notice window (est.) | E5: ORA19990055 | F5: FIFTH AVE COURTS | G5: 733 SW SECOND AVE | H5: PORTLAND | I5: 97204 | J5: 96 | K5: 48 | L5: =IF(OR(J5="",K5=""),"",MAX(J5-K5,0)) -> 48 | M5: Not Indicated | N5: 1999 | O5: =IF(N5="","",Scoring!$B$4-N5) -> 27 | P5: =IF(N5="","",N5+14) -> 2013 | Q5: =IF(N5="","",IF(N5<Scoring!$B$12,"n/a (pre-1990)",N5+Scoring!$B$13)) -> 2028 | R5: =IF(J5="","Unknown",IF(J5>=5,"Yes","No (under 5 units)")) -> Yes | AA5: =IF(U5<>"",(U5-Scoring!$B$3)/365.25,IF(N5="","",IF(N5<Scoring!$B$12,"",(DATE(N5+Scoring!$B$13,12,31)-Scoring!$B$3)/365.25))) -> 2.2477755 | AB5: =IF(T5="Y",0,IF(OR(D5="Expired (verified)",D5="Expiring: notice window (verified)",D5="Expiring: 10-yr horizon (verified)",D5="Past 30-yr mark (verify)",D5="30-yr mark: notice window (est.)",D5="Year-15 window"),1,0)+IF(ISNUMBER(O5),IF(O5>=Scoring!$B$10,1,0),0)+IF(AND(ISNUMBER(L5),ISNUMBER(J5)),IF(J5>0,IF(L5/J5>=Scoring!$B$11,1,0),0),0)+IF(ISNUMBER(Z5),MIN(Z5,3),0)) -> 3 | AC5: =IF(AB5>=3,Scoring!$C$24,IF(AB5=2,Scoring!$C$23,IF(AB5=1,Scoring!$C$22,0))) -> 25 | AD5: =IF(T5="Y",0,IF(ISNUMBER(X5),IF(X5>0.7,Scoring!$C$25,IF(X5>=0.5,Scoring!$C$26,IF(X5>=0.3,Scoring!$C$27,Scoring!$C$28))),Scoring!$C$29)) -> 10 | AE5: =IF(D5="Expiring: notice window (verified)",Scoring!$C$30,IF(OR(D5="Expired (verified)",D5="30-yr mark: notice window (est.)",D5="Year-15 window"),Scoring!$C$31,IF(D5="Expiring: 10-yr horizon (verified)",Scoring!$C$32,IF(D5="Past 30-yr mark (verify)",Scoring!$C$33,IF(OR(D5="Credit period",D5="Superseded record"),Scoring!$C$35,Scoring!$C$34))))) -> 14 | AF5: =IF(T5="Y",0,IF(ISNUMBER(V5),IF(Scoring!$B$4-V5>15,Scoring!$C$36,IF(Scoring!$B$4-V5>=10,Scoring!$C$37,IF(Scoring!$B$4-V5>=5,Scoring!$C$38,Scoring!$C$39))),IF(OR(N5="",D5="Out of program"),Scoring!$C$40,IF(O5>15,Scoring!$C$36,IF(O5>=10,Scoring!$C$37,IF(O5>=5,Scoring!$C$38,Scoring!$C$39)))))) -> 15 | AG5: =IF(T5="Y",0,IF(Y5="Y",Scoring!$C$41,IF(ISNUMBER(O5),IF(O5>=25,Scoring!$C$42,IF(O5>=15,Scoring!$C$43,Scoring!$C$44)),Scoring!$C$44))) -> 8 | AH5: =IF(T5="Y",0,IF(W5="",Scoring!$C$49,IFERROR(VLOOKUP(W5,Scoring!$B$45:$C$48,2,FALSE()),Scoring!$C$49))) -> 5 | AI5: =C5+IF(ISNUMBER(J5),J5,0)/100000+(10000-ROW())/1000000000 -> 77.00097
A6: =RANK(AI6,$AI$2:$AI$755) -> 5 | B6: =IF(T6="Y","Superseded",IF(C6>=Scoring!$B$16,"Immediate",IF(C6>=Scoring!$B$17,"This week",IF(C6>=Scoring!$B$18,"Nurture","Low")))) -> Immediate | C6: =SUM(AC6:AH6) -> 77 | D6: =IF(T6="Y","Superseded record",IF(AND(U6<>"",AA6<0),"Expired (verified)",IF(AND(U6<>"",AA6<=Scoring!$B$5),"Expiring: notice window (verified)",IF(AND(U6<>"",AA6<=Scoring!$B$6),"Expiring: 10-yr horizon (verified)",IF(M6="No Longer Monitored","Out of program",IF(N6="","Unknown vintage",IF(N6<Scoring!$B$12,"Pre-1990, still listed",IF(AND(U6="",AA6<0),"Past 30-yr mark (verify)",IF(AND(U6="",AA6<=Scoring!$B$5),"30-yr mark: notice window (est.)",IF(AND(O6>=Scoring!$B$7,O6<=Scoring!$B$8),"Year-15 window",IF(O6>=Scoring!$B$9,"Recap window",IF(O6>=11,"Late compliance","Credit period")))))))))))) -> 30-yr mark: notice window (est.) | E6: ORA19970035 | F6: FLOYD LIGHT APTS | G6: 1031 SE 106TH AVE | H6: PORTLAND | I6: 97216 | J6: 51 | K6: 23 | L6: =IF(OR(J6="",K6=""),"",MAX(J6-K6,0)) -> 28 | M6: Not Indicated | N6: 1997 | O6: =IF(N6="","",Scoring!$B$4-N6) -> 29 | P6: =IF(N6="","",N6+14) -> 2011 | Q6: =IF(N6="","",IF(N6<Scoring!$B$12,"n/a (pre-1990)",N6+Scoring!$B$13)) -> 2026 | R6: =IF(J6="","Unknown",IF(J6>=5,"Yes","No (under 5 units)")) -> Yes | AA6: =IF(U6<>"",(U6-Scoring!$B$3)/365.25,IF(N6="","",IF(N6<Scoring!$B$12,"",(DATE(N6+Scoring!$B$13,12,31)-Scoring!$B$3)/365.25))) -> 0.24640657 | AB6: =IF(T6="Y",0,IF(OR(D6="Expired (verified)",D6="Expiring: notice window (verified)",D6="Expiring: 10-yr horizon (verified)",D6="Past 30-yr mark (verify)",D6="30-yr mark: notice window (est.)",D6="Year-15 window"),1,0)+IF(ISNUMBER(O6),IF(O6>=Scoring!$B$10,1,0),0)+IF(AND(ISNUMBER(L6),ISNUMBER(J6)),IF(J6>0,IF(L6/J6>=Scoring!$B$11,1,0),0),0)+IF(ISNUMBER(Z6),MIN(Z6,3),0)) -> 3 | AC6: =IF(AB6>=3,Scoring!$C$24,IF(AB6=2,Scoring!$C$23,IF(AB6=1,Scoring!$C$22,0))) -> 25 | AD6: =IF(T6="Y",0,IF(ISNUMBER(X6),IF(X6>0.7,Scoring!$C$25,IF(X6>=0.5,Scoring!$C$26,IF(X6>=0.3,Scoring!$C$27,Scoring!$C$28))),Scoring!$C$29)) -> 10 | AE6: =IF(D6="Expiring: notice window (verified)",Scoring!$C$30,IF(OR(D6="Expired (verified)",D6="30-yr mark: notice window (est.)",D6="Year-15 window"),Scoring!$C$31,IF(D6="Expiring: 10-yr horizon (verified)",Scoring!$C$32,IF(D6="Past 30-yr mark (verify)",Scoring!$C$33,IF(OR(D6="Credit period",D6="Superseded record"),Scoring!$C$35,Scoring!$C$34))))) -> 14 | AF6: =IF(T6="Y",0,IF(ISNUMBER(V6),IF(Scoring!$B$4-V6>15,Scoring!$C$36,IF(Scoring!$B$4-V6>=10,Scoring!$C$37,IF(Scoring!$B$4-V6>=5,Scoring!$C$38,Scoring!$C$39))),IF(OR(N6="",D6="Out of program"),Scoring!$C$40,IF(O6>15,Scoring!$C$36,IF(O6>=10,Scoring!$C$37,IF(O6>=5,Scoring!$C$38,Scoring!$C$39)))))) -> 15 | AG6: =IF(T6="Y",0,IF(Y6="Y",Scoring!$C$41,IF(ISNUMBER(O6),IF(O6>=25,Scoring!$C$42,IF(O6>=15,Scoring!$C$43,Scoring!$C$44)),Scoring!$C$44))) -> 8 | AH6: =IF(T6="Y",0,IF(W6="",Scoring!$C$49,IFERROR(VLOOKUP(W6,Scoring!$B$45:$C$48,2,FALSE()),Scoring!$C$49))) -> 5 | AI6: =C6+IF(ISNUMBER(J6),J6,0)/100000+(10000-ROW())/1000000000 -> 77.00052
A7: =RANK(AI7,$AI$2:$AI$755) -> 6 | B7: =IF(T7="Y","Superseded",IF(C7>=Scoring!$B$16,"Immediate",IF(C7>=Scoring!$B$17,"This week",IF(C7>=Scoring!$B$18,"Nurture","Low")))) -> Immediate | C7: =SUM(AC7:AH7) -> 77 | D7: =IF(T7="Y","Superseded record",IF(AND(U7<>"",AA7<0),"Expired (verified)",IF(AND(U7<>"",AA7<=Scoring!$B$5),"Expiring: notice window (verified)",IF(AND(U7<>"",AA7<=Scoring!$B$6),"Expiring: 10-yr horizon (verified)",IF(M7="No Longer Monitored","Out of program",IF(N7="","Unknown vintage",IF(N7<Scoring!$B$12,"Pre-1990, still listed",IF(AND(U7="",AA7<0),"Past 30-yr mark (verify)",IF(AND(U7="",AA7<=Scoring!$B$5),"30-yr mark: notice window (est.)",IF(AND(O7>=Scoring!$B$7,O7<=Scoring!$B$8),"Year-15 window",IF(O7>=Scoring!$B$9,"Recap window",IF(O7>=11,"Late compliance","Credit period")))))))))))) -> 30-yr mark: notice window (est.) | E7: ORA19990040 | F7: COLUMBIA VIEW APTS | G7: 1695 OAK ST | H7: HOOD RIVER | I7: 97031 | J7: 48 | K7: 40 | L7: =IF(OR(J7="",K7=""),"",MAX(J7-K7,0)) -> 8 | M7: Not Indicated | N7: 1999 | O7: =IF(N7="","",Scoring!$B$4-N7) -> 27 | P7: =IF(N7="","",N7+14) -> 2013 | Q7: =IF(N7="","",IF(N7<Scoring!$B$12,"n/a (pre-1990)",N7+Scoring!$B$13)) -> 2028 | R7: =IF(J7="","Unknown",IF(J7>=5,"Yes","No (under 5 units)")) -> Yes | AA7: =IF(U7<>"",(U7-Scoring!$B$3)/365.25,IF(N7="","",IF(N7<Scoring!$B$12,"",(DATE(N7+Scoring!$B$13,12,31)-Scoring!$B$3)/365.25))) -> 2.2477755 | AB7: =IF(T7="Y",0,IF(OR(D7="Expired (verified)",D7="Expiring: notice window (verified)",D7="Expiring: 10-yr horizon (verified)",D7="Past 30-yr mark (verify)",D7="30-yr mark: notice window (est.)",D7="Year-15 window"),1,0)+IF(ISNUMBER(O7),IF(O7>=Scoring!$B$10,1,0),0)+IF(AND(ISNUMBER(L7),ISNUMBER(J7)),IF(J7>0,IF(L7/J7>=Scoring!$B$11,1,0),0),0)+IF(ISNUMBER(Z7),MIN(Z7,3),0)) -> 3 | AC7: =IF(AB7>=3,Scoring!$C$24,IF(AB7=2,Scoring!$C$23,IF(AB7=1,Scoring!$C$22,0))) -> 25 | AD7: =IF(T7="Y",0,IF(ISNUMBER(X7),IF(X7>0.7,Scoring!$C$25,IF(X7>=0.5,Scoring!$C$26,IF(X7>=0.3,Scoring!$C$27,Scoring!$C$28))),Scoring!$C$29)) -> 10 | AE7: =IF(D7="Expiring: notice window (verified)",Scoring!$C$30,IF(OR(D7="Expired (verified)",D7="30-yr mark: notice window (est.)",D7="Year-15 window"),Scoring!$C$31,IF(D7="Expiring: 10-yr horizon (verified)",Scoring!$C$32,IF(D7="Past 30-yr mark (verify)",Scoring!$C$33,IF(OR(D7="Credit period",D7="Superseded record"),Scoring!$C$35,Scoring!$C$34))))) -> 14 | AF7: =IF(T7="Y",0,IF(ISNUMBER(V7),IF(Scoring!$B$4-V7>15,Scoring!$C$36,IF(Scoring!$B$4-V7>=10,Scoring!$C$37,IF(Scoring!$B$4-V7>=5,Scoring!$C$38,Scoring!$C$39))),IF(OR(N7="",D7="Out of program"),Scoring!$C$40,IF(O7>15,Scoring!$C$36,IF(O7>=10,Scoring!$C$37,IF(O7>=5,Scoring!$C$38,Scoring!$C$39)))))) -> 15 | AG7: =IF(T7="Y",0,IF(Y7="Y",Scoring!$C$41,IF(ISNUMBER(O7),IF(O7>=25,Scoring!$C$42,IF(O7>=15,Scoring!$C$43,Scoring!$C$44)),Scoring!$C$44))) -> 8 | AH7: =IF(T7="Y",0,IF(W7="",Scoring!$C$49,IFERROR(VLOOKUP(W7,Scoring!$B$45:$C$48,2,FALSE()),Scoring!$C$49))) -> 5 | AI7: =C7+IF(ISNUMBER(J7),J7,0)/100000+(10000-ROW())/1000000000 -> 77.00049
A8: =RANK(AI8,$AI$2:$AI$755) -> 7 | B8: =IF(T8="Y","Superseded",IF(C8>=Scoring!$B$16,"Immediate",IF(C8>=Scoring!$B$17,"This week",IF(C8>=Scoring!$B$18,"Nurture","Low")))) -> Immediate | C8: =SUM(AC8:AH8) -> 77 | D8: =IF(T8="Y","Superseded record",IF(AND(U8<>"",AA8<0),"Expired (verified)",IF(AND(U8<>"",AA8<=Scoring!$B$5),"Expiring: notice window (verified)",IF(AND(U8<>"",AA8<=Scoring!$B$6),"Expiring: 10-yr horizon (verified)",IF(M8="No Longer Monitored","Out of program",IF(N8="","Unknown vintage",IF(N8<Scoring!$B$12,"Pre-1990, still listed",IF(AND(U8="",AA8<0),"Past 30-yr mark (verify)",IF(AND(U8="",AA8<=Scoring!$B$5),"30-yr mark: notice window (est.)",IF(AND(O8>=Scoring!$B$7,O8<=Scoring!$B$8),"Year-15 window",IF(O8>=Scoring!$B$9,"Recap window",IF(O8>=11,"Late compliance","Credit period")))))))))))) -> 30-yr mark: notice window (est.) | E8: ORA19990005 | F8: AMES CREEK COURT | G8: 1815 AMES CREEK RD | H8: SWEET HOME | I8: 97386 | J8: 31 | K8: 16 | L8: =IF(OR(J8="",K8=""),"",MAX(J8-K8,0)) -> 15 | M8: Not Indicated | N8: 1999 | O8: =IF(N8="","",Scoring!$B$4-N8) -> 27 | P8: =IF(N8="","",N8+14) -> 2013 | Q8: =IF(N8="","",IF(N8<Scoring!$B$12,"n/a (pre-1990)",N8+Scoring!$B$13)) -> 2028 | R8: =IF(J8="","Unknown",IF(J8>=5,"Yes","No (under 5 units)")) -> Yes | AA8: =IF(U8<>"",(U8-Scoring!$B$3)/365.25,IF(N8="","",IF(N8<Scoring!$B$12,"",(DATE(N8+Scoring!$B$13,12,31)-Scoring!$B$3)/365.25))) -> 2.2477755 | AB8: =IF(T8="Y",0,IF(OR(D8="Expired (verified)",D8="Expiring: notice window (verified)",D8="Expiring: 10-yr horizon (verified)",D8="Past 30-yr mark (verify)",D8="30-yr mark: notice window (est.)",D8="Year-15 window"),1,0)+IF(ISNUMBER(O8),IF(O8>=Scoring!$B$10,1,0),0)+IF(AND(ISNUMBER(L8),ISNUMBER(J8)),IF(J8>0,IF(L8/J8>=Scoring!$B$11,1,0),0),0)+IF(ISNUMBER(Z8),MIN(Z8,3),0)) -> 3 | AC8: =IF(AB8>=3,Scoring!$C$24,IF(AB8=2,Scoring!$C$23,IF(AB8=1,Scoring!$C$22,0))) -> 25 | AD8: =IF(T8="Y",0,IF(ISNUMBER(X8),IF(X8>0.7,Scoring!$C$25,IF(X8>=0.5,Scoring!$C$26,IF(X8>=0.3,Scoring!$C$27,Scoring!$C$28))),Scoring!$C$29)) -> 10 | AE8: =IF(D8="Expiring: notice window (verified)",Scoring!$C$30,IF(OR(D8="Expired (verified)",D8="30-yr mark: notice window (est.)",D8="Year-15 window"),Scoring!$C$31,IF(D8="Expiring: 10-yr horizon (verified)",Scoring!$C$32,IF(D8="Past 30-yr mark (verify)",Scoring!$C$33,IF(OR(D8="Credit period",D8="Superseded record"),Scoring!$C$35,Scoring!$C$34))))) -> 14 | AF8: =IF(T8="Y",0,IF(ISNUMBER(V8),IF(Scoring!$B$4-V8>15,Scoring!$C$36,IF(Scoring!$B$4-V8>=10,Scoring!$C$37,IF(Scoring!$B$4-V8>=5,Scoring!$C$38,Scoring!$C$39))),IF(OR(N8="",D8="Out of program"),Scoring!$C$40,IF(O8>15,Scoring!$C$36,IF(O8>=10,Scoring!$C$37,IF(O8>=5,Scoring!$C$38,Scoring!$C$39)))))) -> 15 | AG8: =IF(T8="Y",0,IF(Y8="Y",Scoring!$C$41,IF(ISNUMBER(O8),IF(O8>=25,Scoring!$C$42,IF(O8>=15,Scoring!$C$43,Scoring!$C$44)),Scoring!$C$44))) -> 8 | AH8: =IF(T8="Y",0,IF(W8="",Scoring!$C$49,IFERROR(VLOOKUP(W8,Scoring!$B$45:$C$48,2,FALSE()),Scoring!$C$49))) -> 5 | AI8: =C8+IF(ISNUMBER(J8),J8,0)/100000+(10000-ROW())/1000000000 -> 77.00032
A9: =RANK(AI9,$AI$2:$AI$755) -> 8 | B9: =IF(T9="Y","Superseded",IF(C9>=Scoring!$B$16,"Immediate",IF(C9>=Scoring!$B$17,"This week",IF(C9>=Scoring!$B$18,"Nurture","Low")))) -> Immediate | C9: =SUM(AC9:AH9) -> 77 | D9: =IF(T9="Y","Superseded record",IF(AND(U9<>"",AA9<0),"Expired (verified)",IF(AND(U9<>"",AA9<=Scoring!$B$5),"Expiring: notice window (verified)",IF(AND(U9<>"",AA9<=Scoring!$B$6),"Expiring: 10-yr horizon (verified)",IF(M9="No Longer Monitored","Out of program",IF(N9="","Unknown vintage",IF(N9<Scoring!$B$12,"Pre-1990, still listed",IF(AND(U9="",AA9<0),"Past 30-yr mark (verify)",IF(AND(U9="",AA9<=Scoring!$B$5),"30-yr mark: notice window (est.)",IF(AND(O9>=Scoring!$B$7,O9<=Scoring!$B$8),"Year-15 window",IF(O9>=Scoring!$B$9,"Recap window",IF(O9>=11,"Late compliance","Credit period")))))))))))) -> 30-yr mark: notice window (est.) | E9: ORA19990130 | F9: RONDEL COURT | G9: 180 FENTON AVE | H9: MOLALLA | I9: 97038 | J9: 30 | K9: 27 | L9: =IF(OR(J9="",K9=""),"",MAX(J9-K9,0)) -> 3 | M9: Not Indicated | N9: 1999 | O9: =IF(N9="","",Scoring!$B$4-N9) -> 27 | P9: =IF(N9="","",N9+14) -> 2013 | Q9: =IF(N9="","",IF(N9<Scoring!$B$12,"n/a (pre-1990)",N9+Scoring!$B$13)) -> 2028 | R9: =IF(J9="","Unknown",IF(J9>=5,"Yes","No (under 5 units)")) -> Yes | AA9: =IF(U9<>"",(U9-Scoring!$B$3)/365.25,IF(N9="","",IF(N9<Scoring!$B$12,"",(DATE(N9+Scoring!$B$13,12,31)-Scoring!$B$3)/365.25))) -> 2.2477755 | AB9: =IF(T9="Y",0,IF(OR(D9="Expired (verified)",D9="Expiring: notice window (verified)",D9="Expiring: 10-yr horizon (verified)",D9="Past 30-yr mark (verify)",D9="30-yr mark: notice window (est.)",D9="Year-15 window"),1,0)+IF(ISNUMBER(O9),IF(O9>=Scoring!$B$10,1,0),0)+IF(AND(ISNUMBER(L9),ISNUMBER(J9)),IF(J9>0,IF(L9/J9>=Scoring!$B$11,1,0),0),0)+IF(ISNUMBER(Z9),MIN(Z9,3),0)) -> 3 | AC9: =IF(AB9>=3,Scoring!$C$24,IF(AB9=2,Scoring!$C$23,IF(AB9=1,Scoring!$C$22,0))) -> 25 | AD9: =IF(T9="Y",0,IF(ISNUMBER(X9),IF(X9>0.7,Scoring!$C$25,IF(X9>=0.5,Scoring!$C$26,IF(X9>=0.3,Scoring!$C$27,Scoring!$C$28))),Scoring!$C$29)) -> 10 | AE9: =IF(D9="Expiring: notice window (verified)",Scoring!$C$30,IF(OR(D9="Expired (verified)",D9="30-yr mark: notice window (est.)",D9="Year-15 window"),Scoring!$C$31,IF(D9="Expiring: 10-yr horizon (verified)",Scoring!$C$32,IF(D9="Past 30-yr mark (verify)",Scoring!$C$33,IF(OR(D9="Credit period",D9="Superseded record"),Scoring!$C$35,Scoring!$C$34))))) -> 14 | AF9: =IF(T9="Y",0,IF(ISNUMBER(V9),IF(Scoring!$B$4-V9>15,Scoring!$C$36,IF(Scoring!$B$4-V9>=10,Scoring!$C$37,IF(Scoring!$B$4-V9>=5,Scoring!$C$38,Scoring!$C$39))),IF(OR(N9="",D9="Out of program"),Scoring!$C$40,IF(O9>15,Scoring!$C$36,IF(O9>=10,Scoring!$C$37,IF(O9>=5,Scoring!$C$38,Scoring!$C$39)))))) -> 15 | AG9: =IF(T9="Y",0,IF(Y9="Y",Scoring!$C$41,IF(ISNUMBER(O9),IF(O9>=25,Scoring!$C$42,IF(O9>=15,Scoring!$C$43,Scoring!$C$44)),Scoring!$C$44))) -> 8 | AH9: =IF(T9="Y",0,IF(W9="",Scoring!$C$49,IFERROR(VLOOKUP(W9,Scoring!$B$45:$C$48,2,FALSE()),Scoring!$C$49))) -> 5 | AI9: =C9+IF(ISNUMBER(J9),J9,0)/100000+(10000-ROW())/1000000000 -> 77.00031
A10: =RANK(AI10,$AI$2:$AI$755) -> 9 | B10: =IF(T10="Y","Superseded",IF(C10>=Scoring!$B$16,"Immediate",IF(C10>=Scoring!$B$17,"This week",IF(C10>=Scoring!$B$18,"Nurture","Low")))) -> This week | C10: =SUM(AC10:AH10) -> 71 | D10: =IF(T10="Y","Superseded record",IF(AND(U10<>"",AA10<0),"Expired (verified)",IF(AND(U10<>"",AA10<=Scoring!$B$5),"Expiring: notice window (verified)",IF(AND(U10<>"",AA10<=Scoring!$B$6),"Expiring: 10-yr horizon (verified)",IF(M10="No Longer Monitored","Out of program",IF(N10="","Unknown vintage",IF(N10<Scoring!$B$12,"Pre-1990, still listed",IF(AND(U10="",AA10<0),"Past 30-yr mark (verify)",IF(AND(U10="",AA10<=Scoring!$B$5),"30-yr mark: notice window (est.)",IF(AND(O10>=Scoring!$B$7,O10<=Scoring!$B$8),"Year-15 window",IF(O10>=Scoring!$B$9,"Recap window",IF(O10>=11,"Late compliance","Credit period")))))))))))) -> Past 30-yr mark (verify) | E10: ORA19949091 | F10: TWELFTH AVENUE TERRACE | G10: 1529 SW 12TH AVE | H10: PORTLAND | I10: 97201 | J10: 119 | K10: 100 | L10: =IF(OR(J10="",K10=""),"",MAX(J10-K10,0)) -> 19 | M10: Not Indicated | N10: 1994 | O10: =IF(N10="","",Scoring!$B$4-N10) -> 32 | P10: =IF(N10="","",N10+14) -> 2008 | Q10: =IF(N10="","",IF(N10<Scoring!$B$12,"n/a (pre-1990)",N10+Scoring!$B$13)) -> 2023 | R10: =IF(J10="","Unknown",IF(J10>=5,"Yes","No (under 5 units)")) -> Yes | AA10: =IF(U10<>"",(U10-Scoring!$B$3)/365.25,IF(N10="","",IF(N10<Scoring!$B$12,"",(DATE(N10+Scoring!$B$13,12,31)-Scoring!$B$3)/365.25))) -> -2.7542779 | AB10: =IF(T10="Y",0,IF(OR(D10="Expired (verified)",D10="Expiring: notice window (verified)",D10="Expiring: 10-yr horizon (verified)",D10="Past 30-yr mark (verify)",D10="30-yr mark: notice window (est.)",D10="Year-15 window"),1,0)+IF(ISNUMBER(O10),IF(O10>=Scoring!$B$10,1,0),0)+IF(AND(ISNUMBER(L10),ISNUMBER(J10)),IF(J10>0,IF(L10/J10>=Scoring!$B$11,1,0),0),0)+IF(ISNUMBER(Z10),MIN(Z10,3),0)) -> 3 | AC10: =IF(AB10>=3,Scoring!$C$24,IF(AB10=2,Scoring!$C$23,IF(AB10=1,Scoring!$C$22,0))) -> 25 | AD10: =IF(T10="Y",0,IF(ISNUMBER(X10),IF(X10>0.7,Scoring!$C$25,IF(X10>=0.5,Scoring!$C$26,IF(X10>=0.3,Scoring!$C$27,Scoring!$C$28))),Scoring!$C$29)) -> 10 | AE10: =IF(D10="Expiring: notice window (verified)",Scoring!$C$30,IF(OR(D10="Expired (verified)",D10="30-yr mark: notice window (est.)",D10="Year-15 window"),Scoring!$C$31,IF(D10="Expiring: 10-yr horizon (verified)",Scoring!$C$32,IF(D10="Past 30-yr mark (verify)",Scoring!$C$33,IF(OR(D10="Credit period",D10="Superseded record"),Scoring!$C$35,Scoring!$C$34))))) -> 8 | AF10: =IF(T10="Y",0,IF(ISNUMBER(V10),IF(Scoring!$B$4-V10>15,Scoring!$C$36,IF(Scoring!$B$4-V10>=10,Scoring!$C$37,IF(Scoring!$B$4-V10>=5,Scoring!$C$38,Scoring!$C$39))),IF(OR(N10="",D10="Out of program"),Scoring!$C$40,IF(O10>15,Scoring!$C$36,IF(O10>=10,Scoring!$C$37,IF(O10>=5,Scoring!$C$38,Scoring!$C$39)))))) -> 15 | AG10: =IF(T10="Y",0,IF(Y10="Y",Scoring!$C$41,IF(ISNUMBER(O10),IF(O10>=25,Scoring!$C$42,IF(O10>=15,Scoring!$C$43,Scoring!$C$44)),Scoring!$C$44))) -> 8 | AH10: =IF(T10="Y",0,IF(W10="",Scoring!$C$49,IFERROR(VLOOKUP(W10,Scoring!$B$45:$C$48,2,FALSE()),Scoring!$C$49))) -> 5 | AI10: =C10+IF(ISNUMBER(J10),J10,0)/100000+(10000-ROW())/1000000000 -> 71.0012
A11: =RANK(AI11,$AI$2:$AI$755) -> 10 | B11: =IF(T11="Y","Superseded",IF(C11>=Scoring!$B$16,"Immediate",IF(C11>=Scoring!$B$17,"This week",IF(C11>=Scoring!$B$18,"Nurture","Low")))) -> This week | C11: =SUM(AC11:AH11) -> 71 | D11: =IF(T11="Y","Superseded record",IF(AND(U11<>"",AA11<0),"Expired (verified)",IF(AND(U11<>"",AA11<=Scoring!$B$5),"Expiring: notice window (verified)",IF(AND(U11<>"",AA11<=Scoring!$B$6),"Expiring: 10-yr horizon (verified)",IF(M11="No Longer Monitored","Out of program",IF(N11="","Unknown vintage",IF(N11<Scoring!$B$12,"Pre-1990, still listed",IF(AND(U11="",AA11<0),"Past 30-yr mark (verify)",IF(AND(U11="",AA11<=Scoring!$B$5),"30-yr mark: notice window (est.)",IF(AND(O11>=Scoring!$B$7,O11<=Scoring!$B$8),"Year-15 window",IF(O11>=Scoring!$B$9,"Recap window",IF(O11>=11,"Late compliance","Credit period")))))))))))) -> Past 30-yr mark (verify) | E11: ORA19940065 | F11: ST JAMES | G11: 1320 SW TENTH AVE | H11: PORTLAND | J11: 109 | K11: 98 | L11: =IF(OR(J11="",K11=""),"",MAX(J11-K11,0)) -> 11 | M11: Not Indicated | N11: 1994 | O11: =IF(N11="","",Scoring!$B$4-N11) -> 32 | P11: =IF(N11="","",N11+14) -> 2008 | Q11: =IF(N11="","",IF(N11<Scoring!$B$12,"n/a (pre-1990)",N11+Scoring!$B$13)) -> 2023 | R11: =IF(J11="","Unknown",IF(J11>=5,"Yes","No (under 5 units)")) -> Yes | AA11: =IF(U11<>"",(U11-Scoring!$B$3)/365.25,IF(N11="","",IF(N11<Scoring!$B$12,"",(DATE(N11+Scoring!$B$13,12,31)-Scoring!$B$3)/365.25))) -> -2.7542779 | AB11: =IF(T11="Y",0,IF(OR(D11="Expired (verified)",D11="Expiring: notice window (verified)",D11="Expiring: 10-yr horizon (verified)",D11="Past 30-yr mark (verify)",D11="30-yr mark: notice window (est.)",D11="Year-15 window"),1,0)+IF(ISNUMBER(O11),IF(O11>=Scoring!$B$10,1,0),0)+IF(AND(ISNUMBER(L11),ISNUMBER(J11)),IF(J11>0,IF(L11/J11>=Scoring!$B$11,1,0),0),0)+IF(ISNUMBER(Z11),MIN(Z11,3),0)) -> 3 | AC11: =IF(AB11>=3,Scoring!$C$24,IF(AB11=2,Scoring!$C$23,IF(AB11=1,Scoring!$C$22,0))) -> 25 | AD11: =IF(T11="Y",0,IF(ISNUMBER(X11),IF(X11>0.7,Scoring!$C$25,IF(X11>=0.5,Scoring!$C$26,IF(X11>=0.3,Scoring!$C$27,Scoring!$C$28))),Scoring!$C$29)) -> 10 | AE11: =IF(D11="Expiring: notice window (verified)",Scoring!$C$30,IF(OR(D11="Expired (verified)",D11="30-yr mark: notice window (est.)",D11="Year-15 window"),Scoring!$C$31,IF(D11="Expiring: 10-yr horizon (verified)",Scoring!$C$32,IF(D11="Past 30-yr mark (verify)",Scoring!$C$33,IF(OR(D11="Credit period",D11="Superseded record"),Scoring!$C$35,Scoring!$C$34))))) -> 8 | AF11: =IF(T11="Y",0,IF(ISNUMBER(V11),IF(Scoring!$B$4-V11>15,Scoring!$C$36,IF(Scoring!$B$4-V11>=10,Scoring!$C$37,IF(Scoring!$B$4-V11>=5,Scoring!$C$38,Scoring!$C$39))),IF(OR(N11="",D11="Out of program"),Scoring!$C$40,IF(O11>15,Scoring!$C$36,IF(O11>=10,Scoring!$C$37,IF(O11>=5,Scoring!$C$38,Scoring!$C$39)))))) -> 15 | AG11: =IF(T11="Y",0,IF(Y11="Y",Scoring!$C$41,IF(ISNUMBER(O11),IF(O11>=25,Scoring!$C$42,IF(O11>=15,Scoring!$C$43,Scoring!$C$44)),Scoring!$C$44))) -> 8 | AH11: =IF(T11="Y",0,IF(W11="",Scoring!$C$49,IFERROR(VLOOKUP(W11,Scoring!$B$45:$C$48,2,FALSE()),Scoring!$C$49))) -> 5 | AI11: =C11+IF(ISNUMBER(J11),J11,0)/100000+(10000-ROW())/1000000000 -> 71.0011
A12: =RANK(AI12,$AI$2:$AI$755) -> 11 | B12: =IF(T12="Y","Superseded",IF(C12>=Scoring!$B$16,"Immediate",IF(C12>=Scoring!$B$17,"This week",IF(C12>=Scoring!$B$18,"Nurture","Low")))) -> This week | C12: =SUM(AC12:AH12) -> 71 | D12: =IF(T12="Y","Superseded record",IF(AND(U12<>"",AA12<0),"Expired (verified)",IF(AND(U12<>"",AA12<=Scoring!$B$5),"Expiring: notice window (verified)",IF(AND(U12<>"",AA12<=Scoring!$B$6),"Expiring: 10-yr horizon (verified)",IF(M12="No Longer Monitored","Out of program",IF(N12="","Unknown vintage",IF(N12<Scoring!$B$12,"Pre-1990, still listed",IF(AND(U12="",AA12<0),"Past 30-yr mark (verify)",IF(AND(U12="",AA12<=Scoring!$B$5),"30-yr mark: notice window (est.)",IF(AND(O12>=Scoring!$B$7,O12<=Scoring!$B$8),"Year-15 window",IF(O12>=Scoring!$B$9,"Recap window",IF(O12>=11,"Late compliance","Credit period")))))))))))) -> Past 30-yr mark (verify) | E12: ORA19930062 | F12: STONEYBROOK | G12: 933 NW CANAL BLVD | H12: REDMOND | I12: 97756 | J12: 50 | K12: 40 | L12: =IF(OR(J12="",K12=""),"",MAX(J12-K12,0)) -> 10 | M12: Not Indicated | N12: 1993 | O12: =IF(N12="","",Scoring!$B$4-N12) -> 33 | P12: =IF(N12="","",N12+14) -> 2007 | Q12: =IF(N12="","",IF(N12<Scoring!$B$12,"n/a (pre-1990)",N12+Scoring!$B$13)) -> 2022 | R12: =IF(J12="","Unknown",IF(J12>=5,"Yes","No (under 5 units)")) -> Yes | AA12: =IF(U12<>"",(U12-Scoring!$B$3)/365.25,IF(N12="","",IF(N12<Scoring!$B$12,"",(DATE(N12+Scoring!$B$13,12,31)-Scoring!$B$3)/365.25))) -> -3.7535934 | AB12: =IF(T12="Y",0,IF(OR(D12="Expired (verified)",D12="Expiring: notice window (verified)",D12="Expiring: 10-yr horizon (verified)",D12="Past 30-yr mark (verify)",D12="30-yr mark: notice window (est.)",D12="Year-15 window"),1,0)+IF(ISNUMBER(O12),IF(O12>=Scoring!$B$10,1,0),0)+IF(AND(ISNUMBER(L12),ISNUMBER(J12)),IF(J12>0,IF(L12/J12>=Scoring!$B$11,1,0),0),0)+IF(ISNUMBER(Z12),MIN(Z12,3),0)) -> 3 | AC12: =IF(AB12>=3,Scoring!$C$24,IF(AB12=2,Scoring!$C$23,IF(AB12=1,Scoring!$C$22,0))) -> 25 | AD12: =IF(T12="Y",0,IF(ISNUMBER(X12),IF(X12>0.7,Scoring!$C$25,IF(X12>=0.5,Scoring!$C$26,IF(X12>=0.3,Scoring!$C$27,Scoring!$C$28))),Scoring!$C$29)) -> 10 | AE12: =IF(D12="Expiring: notice window (verified)",Scoring!$C$30,IF(OR(D12="Expired (verified)",D12="30-yr mark: notice window (est.)",D12="Year-15 window"),Scoring!$C$31,IF(D12="Expiring: 10-yr horizon (verified)",Scoring!$C$32,IF(D12="Past 30-yr mark (verify)",Scoring!$C$33,IF(OR(D12="Credit period",D12="Superseded record"),Scoring!$C$35,Scoring!$C$34))))) -> 8 | AF12: =IF(T12="Y",0,IF(ISNUMBER(V12),IF(Scoring!$B$4-V12>15,Scoring!$C$36,IF(Scoring!$B$4-V12>=10,Scoring!$C$37,IF(Scoring!$B$4-V12>=5,Scoring!$C$38,Scoring!$C$39))),IF(OR(N12="",D12="Out of program"),Scoring!$C$40,IF(O12>15,Scoring!$C$36,IF(O12>=10,Scoring!$C$37,IF(O12>=5,Scoring!$C$38,Scoring!$C$39)))))) -> 15 | AG12: =IF(T12="Y",0,IF(Y12="Y",Scoring!$C$41,IF(ISNUMBER(O12),IF(O12>=25,Scoring!$C$42,IF(O12>=15,Scoring!$C$43,Scoring!$C$44)),Scoring!$C$44))) -> 8 | AH12: =IF(T12="Y",0,IF(W12="",Scoring!$C$49,IFERROR(VLOOKUP(W12,Scoring!$B$45:$C$48,2,FALSE()),Scoring!$C$49))) -> 5 | AI12: =C12+IF(ISNUMBER(J12),J12,0)/100000+(10000-ROW())/1000000000 -> 71.00051
A13: =RANK(AI13,$AI$2:$AI$755) -> 12 | B13: =IF(T13="Y","Superseded",IF(C13>=Scoring!$B$16,"Immediate",IF(C13>=Scoring!$B$17,"This week",IF(C13>=Scoring!$B$18,"Nurture","Low")))) -> This week | C13: =SUM(AC13:AH13) -> 70 | D13: =IF(T13="Y","Superseded record",IF(AND(U13<>"",AA13<0),"Expired (verified)",IF(AND(U13<>"",AA13<=Scoring!$B$5),"Expiring: notice window (verified)",IF(AND(U13<>"",AA13<=Scoring!$B$6),"Expiring: 10-yr horizon (verified)",IF(M13="No Longer Monitored","Out of program",IF(N13="","Unknown vintage",IF(N13<Scoring!$B$12,"Pre-1990, still listed",IF(AND(U13="",AA13<0),"Past 30-yr mark (verify)",IF(AND(U13="",AA13<=Scoring!$B$5),"30-yr mark: notice window (est.)",IF(AND(O13>=Scoring!$B$7,O13<=Scoring!$B$8),"Year-15 window",IF(O13>=Scoring!$B$9,"Recap window",IF(O13>=11,"Late compliance","Credit period")))))))))))) -> 30-yr mark: notice window (est.) | E13: ORA19980020 | F13: BERRY RIDGE APTS | G13: 2711 W POWELL BLVD | H13: GRESHAM | I13: 97030 | J13: 248 | K13: 248 | L13: =IF(OR(J13="",K13=""),"",MAX(J13-K13,0)) -> 0 | M13: Not Indicated | N13: 1998 | O13: =IF(N13="","",Scoring!$B$4-N13) -> 28 | P13: =IF(N13="","",N13+14) -> 2012 | Q13: =IF(N13="","",IF(N13<Scoring!$B$12,"n/a (pre-1990)",N13+Scoring!$B$13)) -> 2027 | R13: =IF(J13="","Unknown",IF(J13>=5,"Yes","No (under 5 units)")) -> Yes | AA13: =IF(U13<>"",(U13-Scoring!$B$3)/365.25,IF(N13="","",IF(N13<Scoring!$B$12,"",(DATE(N13+Scoring!$B$13,12,31)-Scoring!$B$3)/365.25))) -> 1.2457221 | AB13: =IF(T13="Y",0,IF(OR(D13="Expired (verified)",D13="Expiring: notice window (verified)",D13="Expiring: 10-yr horizon (verified)",D13="Past 30-yr mark (verify)",D13="30-yr mark: notice window (est.)",D13="Year-15 window"),1,0)+IF(ISNUMBER(O13),IF(O13>=Scoring!$B$10,1,0),0)+IF(AND(ISNUMBER(L13),ISNUMBER(J13)),IF(J13>0,IF(L13/J13>=Scoring!$B$11,1,0),0),0)+IF(ISNUMBER(Z13),MIN(Z13,3),0)) -> 2 | AC13: =IF(AB13>=3,Scoring!$C$24,IF(AB13=2,Scoring!$C$23,IF(AB13=1,Scoring!$C$22,0))) -> 18 | AD13: =IF(T13="Y",0,IF(ISNUMBER(X13),IF(X13>0.7,Scoring!$C$25,IF(X13>=0.5,Scoring!$C$26,IF(X13>=0.3,Scoring!$C$27,Scoring!$C$28))),Scoring!$C$29)) -> 10 | AE13: =IF(D13="Expiring: notice window (verified)",Scoring!$C$30,IF(OR(D13="Expired (verified)",D13="30-yr mark: notice window (est.)",D13="Year-15 window"),Scoring!$C$31,IF(D13="Expiring: 10-yr horizon (verified)",Scoring!$C$32,IF(D13="Past 30-yr mark (verify)",Scoring!$C$33,IF(OR(D13="Credit period",D13="Superseded record"),Scoring!$C$35,Scoring!$C$34))))) -> 14 | AF13: =IF(T13="Y",0,IF(ISNUMBER(V13),IF(Scoring!$B$4-V13>15,Scoring!$C$36,IF(Scoring!$B$4-V13>=10,Scoring!$C$37,IF(Scoring!$B$4-V13>=5,Scoring!$C$38,Scoring!$C$39))),IF(OR(N13="",D13="Out of program"),Scoring!$C$40,IF(O13>15,Scoring!$C$36,IF(O13>=10,Scoring!$C$37,IF(O13>=5,Scoring!$C$38,Scoring!$C$39)))))) -> 15 | AG13: =IF(T13="Y",0,IF(Y13="Y",Scoring!$C$41,IF(ISNUMBER(O13),IF(O13>=25,Scoring!$C$42,IF(O13>=15,Scoring!$C$43,Scoring!$C$44)),Scoring!$C$44))) -> 8 | AH13: =IF(T13="Y",0,IF(W13="",Scoring!$C$49,IFERROR(VLOOKUP(W13,Scoring!$B$45:$C$48,2,FALSE()),Scoring!$C$49))) -> 5 | AI13: =C13+IF(ISNUMBER(J13),J13,0)/100000+(10000-ROW())/1000000000 -> 70.00249
A14: =RANK(AI14,$AI$2:$AI$755) -> 13 | B14: =IF(T14="Y","Superseded",IF(C14>=Scoring!$B$16,"Immediate",IF(C14>=Scoring!$B$17,"This week",IF(C14>=Scoring!$B$18,"Nurture","Low")))) -> This week | C14: =SUM(AC14:AH14) -> 70 | D14: =IF(T14="Y","Superseded record",IF(AND(U14<>"",AA14<0),"Expired (verified)",IF(AND(U14<>"",AA14<=Scoring!$B$5),"Expiring: notice window (verified)",IF(AND(U14<>"",AA14<=Scoring!$B$6),"Expiring: 10-yr horizon (verified)",IF(M14="No Longer Monitored","Out of program",IF(N14="","Unknown vintage",IF(N14<Scoring!$B$12,"Pre-1990, still listed",IF(AND(U14="",AA14<0),"Past 30-yr mark (verify)",IF(AND(U14="",AA14<=Scoring!$B$5),"30-yr mark: notice window (est.)",IF(AND(O14>=Scoring!$B$7,O14<=Scoring!$B$8),"Year-15 window",IF(O14>=Scoring!$B$9,"Recap window",IF(O14>=11,"Late compliance","Credit period")))))))))))) -> 30-yr mark: notice window (est.) | E14: ORA19999166 | F14: BRIARCREEK APTS | G14: 1008 NW BRIARCREEK WAY | H14: HILLSBORO | I14: 97006 | J14: 216 | K14: 216 | L14: =IF(OR(J14="",K14=""),"",MAX(J14-K14,0)) -> 0 | M14: Not Indicated | N14: 1999 | O14: =IF(N14="","",Scoring!$B$4-N14) -> 27 | P14: =IF(N14="","",N14+14) -> 2013 | Q14: =IF(N14="","",IF(N14<Scoring!$B$12,"n/a (pre-1990)",N14+Scoring!$B$13)) -> 2028 | R14: =IF(J14="","Unknown",IF(J14>=5,"Yes","No (under 5 units)")) -> Yes | AA14: =IF(U14<>"",(U14-Scoring!$B$3)/365.25,IF(N14="","",IF(N14<Scoring!$B$12,"",(DATE(N14+Scoring!$B$13,12,31)-Scoring!$B$3)/365.25))) -> 2.2477755 | AB14: =IF(T14="Y",0,IF(OR(D14="Expired (verified)",D14="Expiring: notice window (verified)",D14="Expiring: 10-yr horizon (verified)",D14="Past 30-yr mark (verify)",D14="30-yr mark: notice window (est.)",D14="Year-15 window"),1,0)+IF(ISNUMBER(O14),IF(O14>=Scoring!$B$10,1,0),0)+IF(AND(ISNUMBER(L14),ISNUMBER(J14)),IF(J14>0,IF(L14/J14>=Scoring!$B$11,1,0),0),0)+IF(ISNUMBER(Z14),MIN(Z14,3),0)) -> 2 | AC14: =IF(AB14>=3,Scoring!$C$24,IF(AB14=2,Scoring!$C$23,IF(AB14=1,Scoring!$C$22,0))) -> 18 | AD14: =IF(T14="Y",0,IF(ISNUMBER(X14),IF(X14>0.7,Scoring!$C$25,IF(X14>=0.5,Scoring!$C$26,IF(X14>=0.3,Scoring!$C$27,Scoring!$C$28))),Scoring!$C$29)) -> 10 | AE14: =IF(D14="Expiring: notice window (verified)",Scoring!$C$30,IF(OR(D14="Expired (verified)",D14="30-yr mark: notice window (est.)",D14="Year-15 window"),Scoring!$C$31,IF(D14="Expiring: 10-yr horizon (verified)",Scoring!$C$32,IF(D14="Past 30-yr mark (verify)",Scoring!$C$33,IF(OR(D14="Credit period",D14="Superseded record"),Scoring!$C$35,Scoring!$C$34))))) -> 14 | AF14: =IF(T14="Y",0,IF(ISNUMBER(V14),IF(Scoring!$B$4-V14>15,Scoring!$C$36,IF(Scoring!$B$4-V14>=10,Scoring!$C$37,IF(Scoring!$B$4-V14>=5,Scoring!$C$38,Scoring!$C$39))),IF(OR(N14="",D14="Out of program"),Scoring!$C$40,IF(O14>15,Scoring!$C$36,IF(O14>=10,Scoring!$C$37,IF(O14>=5,Scoring!$C$38,Scoring!$C$39)))))) -> 15 | AG14: =IF(T14="Y",0,IF(Y14="Y",Scoring!$C$41,IF(ISNUMBER(O14),IF(O14>=25,Scoring!$C$42,IF(O14>=15,Scoring!$C$43,Scoring!$C$44)),Scoring!$C$44))) -> 8 | AH14: =IF(T14="Y",0,IF(W14="",Scoring!$C$49,IFERROR(VLOOKUP(W14,Scoring!$B$45:$C$48,2,FALSE()),Scoring!$C$49))) -> 5 | AI14: =C14+IF(ISNUMBER(J14),J14,0)/100000+(10000-ROW())/1000000000 -> 70.00217
A15: =RANK(AI15,$AI$2:$AI$755) -> 14 | B15: =IF(T15="Y","Superseded",IF(C15>=Scoring!$B$16,"Immediate",IF(C15>=Scoring!$B$17,"This week",IF(C15>=Scoring!$B$18,"Nurture","Low")))) -> This week | C15: =SUM(AC15:AH15) -> 70 | D15: =IF(T15="Y","Superseded record",IF(AND(U15<>"",AA15<0),"Expired (verified)",IF(AND(U15<>"",AA15<=Scoring!$B$5),"Expiring: notice window (verified)",IF(AND(U15<>"",AA15<=Scoring!$B$6),"Expiring: 10-yr horizon (verified)",IF(M15="No Longer Monitored","Out of program",IF(N15="","Unknown vintage",IF(N15<Scoring!$B$12,"Pre-1990, still listed",IF(AND(U15="",AA15<0),"Past 30-yr mark (verify)",IF(AND(U15="",AA15<=Scoring!$B$5),"30-yr mark: notice window (est.)",IF(AND(O15>=Scoring!$B$7,O15<=Scoring!$B$8),"Year-15 window",IF(O15>=Scoring!$B$9,"Recap window",IF(O15>=11,"Late compliance","Credit period")))))))))))) -> 30-yr mark: notice window (est.) | E15: ORA19970020 | F15: BETHANY MEADOWS I | G15: 16140 NW SPARTAN WAY | H15: PORTLAND | I15: 97229 | J15: 208 | K15: 208 | L15: =IF(OR(J15="",K15=""),"",MAX(J15-K15,0)) -> 0 | M15: Not Indicated | N15: 1997 | O15: =IF(N15="","",Scoring!$B$4-N15) -> 29 | P15: =IF(N15="","",N15+14) -> 2011 | Q15: =IF(N15="","",IF(N15<Scoring!$B$12,"n/a (pre-1990)",N15+Scoring!$B$13)) -> 2026 | R15: =IF(J15="","Unknown",IF(J15>=5,"Yes","No (under 5 units)")) -> Yes | AA15: =IF(U15<>"",(U15-Scoring!$B$3)/365.25,IF(N15="","",IF(N15<Scoring!$B$12,"",(DATE(N15+Scoring!$B$13,12,31)-Scoring!$B$3)/365.25))) -> 0.24640657 | AB15: =IF(T15="Y",0,IF(OR(D15="Expired (verified)",D15="Expiring: notice window (verified)",D15="Expiring: 10-yr horizon (verified)",D15="Past 30-yr mark (verify)",D15="30-yr mark: notice window (est.)",D15="Year-15 window"),1,0)+IF(ISNUMBER(O15),IF(O15>=Scoring!$B$10,1,0),0)+IF(AND(ISNUMBER(L15),ISNUMBER(J15)),IF(J15>0,IF(L15/J15>=Scoring!$B$11,1,0),0),0)+IF(ISNUMBER(Z15),MIN(Z15,3),0)) -> 2 | AC15: =IF(AB15>=3,Scoring!$C$24,IF(AB15=2,Scoring!$C$23,IF(AB15=1,Scoring!$C$22,0))) -> 18 | AD15: =IF(T15="Y",0,IF(ISNUMBER(X15),IF(X15>0.7,Scoring!$C$25,IF(X15>=0.5,Scoring!$C$26,IF(X15>=0.3,Scoring!$C$27,Scoring!$C$28))),Scoring!$C$29)) -> 10 | AE15: =IF(D15="Expiring: notice window (verified)",Scoring!$C$30,IF(OR(D15="Expired (verified)",D15="30-yr mark: notice window (est.)",D15="Year-15 window"),Scoring!$C$31,IF(D15="Expiring: 10-yr horizon (verified)",Scoring!$C$32,IF(D15="Past 30-yr mark (verify)",Scoring!$C$33,IF(OR(D15="Credit period",D15="Superseded record"),Scoring!$C$35,Scoring!$C$34))))) -> 14 | AF15: =IF(T15="Y",0,IF(ISNUMBER(V15),IF(Scoring!$B$4-V15>15,Scoring!$C$36,IF(Scoring!$B$4-V15>=10,Scoring!$C$37,IF(Scoring!$B$4-V15>=5,Scoring!$C$38,Scoring!$C$39))),IF(OR(N15="",D15="Out of program"),Scoring!$C$40,IF(O15>15,Scoring!$C$36,IF(O15>=10,Scoring!$C$37,IF(O15>=5,Scoring!$C$38,Scoring!$C$39)))))) -> 15 | AG15: =IF(T15="Y",0,IF(Y15="Y",Scoring!$C$41,IF(ISNUMBER(O15),IF(O15>=25,Scoring!$C$42,IF(O15>=15,Scoring!$C$43,Scoring!$C$44)),Scoring!$C$44))) -> 8 | AH15: =IF(T15="Y",0,IF(W15="",Scoring!$C$49,IFERROR(VLOOKUP(W15,Scoring!$B$45:$C$48,2,FALSE()),Scoring!$C$49))) -> 5 | AI15: =C15+IF(ISNUMBER(J15),J15,0)/100000+(10000-ROW())/1000000000 -> 70.00209
A16: =RANK(AI16,$AI$2:$AI$755) -> 15 | B16: =IF(T16="Y","Superseded",IF(C16>=Scoring!$B$16,"Immediate",IF(C16>=Scoring!$B$17,"This week",IF(C16>=Scoring!$B$18,"Nurture","Low")))) -> This week | C16: =SUM(AC16:AH16) -> 70 | D16: =IF(T16="Y","Superseded record",IF(AND(U16<>"",AA16<0),"Expired (verified)",IF(AND(U16<>"",AA16<=Scoring!$B$5),"Expiring: notice window (verified)",IF(AND(U16<>"",AA16<=Scoring!$B$6),"Expiring: 10-yr horizon (verified)",IF(M16="No Longer Monitored","Out of program",IF(N16="","Unknown vintage",IF(N16<Scoring!$B$12,"Pre-1990, still listed",IF(AND(U16="",AA16<0),"Past 30-yr mark (verify)",IF(AND(U16="",AA16<=Scoring!$B$5),"30-yr mark: notice window (est.)",IF(AND(O16>=Scoring!$B$7,O16<=Scoring!$B$8),"Year-15 window",IF(O16>=Scoring!$B$9,"Recap window",IF(O16>=11,"Late compliance","Credit period")))))))))))) -> 30-yr mark: notice window (est.) | E16: ORA19970075 | F16: PEARL COURT APTS | G16: 920 NW KEARNEY ST | H16: PORTLAND | I16: 97209 | J16: 199 | L16: =IF(OR(J16="",K16=""),"",MAX(J16-K16,0)) | M16: Not Indicated | N16: 1997 | O16: =IF(N16="","",Scoring!$B$4-N16) -> 29 | P16: =IF(N16="","",N16+14) -> 2011 | Q16: =IF(N16="","",IF(N16<Scoring!$B$12,"n/a (pre-1990)",N16+Scoring!$B$13)) -> 2026 | R16: =IF(J16="","Unknown",IF(J16>=5,"Yes","No (under 5 units)")) -> Yes | AA16: =IF(U16<>"",(U16-Scoring!$B$3)/365.25,IF(N16="","",IF(N16<Scoring!$B$12,"",(DATE(N16+Scoring!$B$13,12,31)-Scoring!$B$3)/365.25))) -> 0.24640657 | AB16: =IF(T16="Y",0,IF(OR(D16="Expired (verified)",D16="Expiring: notice window (verified)",D16="Expiring: 10-yr horizon (verified)",D16="Past 30-yr mark (verify)",D16="30-yr mark: notice window (est.)",D16="Year-15 window"),1,0)+IF(ISNUMBER(O16),IF(O16>=Scoring!$B$10,1,0),0)+IF(AND(ISNUMBER(L16),ISNUMBER(J16)),IF(J16>0,IF(L16/J16>=Scoring!$B$11,1,0),0),0)+IF(ISNUMBER(Z16),MIN(Z16,3),0)) -> 2 | AC16: =IF(AB16>=3,Scoring!$C$24,IF(AB16=2,Scoring!$C$23,IF(AB16=1,Scoring!$C$22,0))) -> 18 | AD16: =IF(T16="Y",0,IF(ISNUMBER(X16),IF(X16>0.7,Scoring!$C$25,IF(X16>=0.5,Scoring!$C$26,IF(X16>=0.3,Scoring!$C$27,Scoring!$C$28))),Scoring!$C$29)) -> 10 | AE16: =IF(D16="Expiring: notice window (verified)",Scoring!$C$30,IF(OR(D16="Expired (verified)",D16="30-yr mark: notice window (est.)",D16="Year-15 window"),Scoring!$C$31,IF(D16="Expiring: 10-yr horizon (verified)",Scoring!$C$32,IF(D16="Past 30-yr mark (verify)",Scoring!$C$33,IF(OR(D16="Credit period",D16="Superseded record"),Scoring!$C$35,Scoring!$C$34))))) -> 14 | AF16: =IF(T16="Y",0,IF(ISNUMBER(V16),IF(Scoring!$B$4-V16>15,Scoring!$C$36,IF(Scoring!$B$4-V16>=10,Scoring!$C$37,IF(Scoring!$B$4-V16>=5,Scoring!$C$38,Scoring!$C$39))),IF(OR(N16="",D16="Out of program"),Scoring!$C$40,IF(O16>15,Scoring!$C$36,IF(O16>=10,Scoring!$C$37,IF(O16>=5,Scoring!$C$38,Scoring!$C$39)))))) -> 15 | AG16: =IF(T16="Y",0,IF(Y16="Y",Scoring!$C$41,IF(ISNUMBER(O16),IF(O16>=25,Scoring!$C$42,IF(O16>=15,Scoring!$C$43,Scoring!$C$44)),Scoring!$C$44))) -> 8 | AH16: =IF(T16="Y",0,IF(W16="",Scoring!$C$49,IFERROR(VLOOKUP(W16,Scoring!$B$45:$C$48,2,FALSE()),Scoring!$C$49))) -> 5 | AI16: =C16+IF(ISNUMBER(J16),J16,0)/100000+(10000-ROW())/1000000000 -> 70.002
